Workbook

Sheet Your formulary
A1: ASSUMPTIONS, edit these and every line recalculates
A2: Practice share | B2: 0.65
A3: Oral collections | B3: 1
A4: Topical collections | B4: 1
A5: Dispensing fee / Rx | B5: 0
A6: Shipping / order | B6: 6
A7: Per fill across everything marked Keep | B7: =SUMIF(A13:A200,"Yes",J13:J200) | D7: Lines kept | E7: =COUNTIF(A13:A200,"Yes")
A8: Shipping is charged once per order, not per medication. Several medications sent together carry one shipping fee.
A9: Highlighted cells came from the dispensing pharmacist. Annotations, substitutions and quantity changes are his.
A10: Set Keep to No to drop a line. To add one, copy its row from the Full formulary sheet and paste it in below.
A12: Keep | B12: Medication | C12: Brand | D12: Strength | E12: Size | F12: Cost | G12: AWP | H12: PA fee | I12: Ship | J12: Per fill | K12: Status | L12: Source | M12: Note
A13: Yes | B13: Ibuprofen | C13: Motrin | D13: 800mg | E13: 90 | F13: 8.99 | G13: 72 | H13: =ROUND(G13*1.1,2) | I13: =$B$6 | J13: =ROUND((H13*IF(FALSE,$B$4,$B$3)-F13-$B$5-$B$6)*$B$2,2) | K13: Priced
A14: Yes | B14: Ibuprofen/famotidine | C14: Duexis | D14: 800/26.6mg | E14: 90 | F14: 87.28 | G14: 998.1 | H14: =ROUND(G14*1.1,2) | I14: =$B$6 | J14: =ROUND((H14*IF(FALSE,$B$4,$B$3)-F14-$B$5-$B$6)*$B$2,2) | K14: Priced
A15: Yes | B15: Celecoxib | C15: Celebrex | D15: 200mg | E15: 30 | F15: 7.99 | G15: 234 | H15: =ROUND(G15*1.1,2) | I15: =$B$6 | J15: =ROUND((H15*IF(FALSE,$B$4,$B$3)-F15-$B$5-$B$6)*$B$2,2) | K15: Priced
A16: Yes | B16: Celecoxib | C16: Celebrex | D16: 200mg | E16: 60 | F16: 15.99 | G16: 454.2 | H16: =ROUND(G16*1.1,2) | I16: =$B$6 | J16: =ROUND((H16*IF(FALSE,$B$4,$B$3)-F16-$B$5-$B$6)*$B$2,2) | K16: Priced
A17: Yes | B17: Meloxicam | C17: Mobic | D17: 7.5mg | E17: 30 | F17: 54.5 | G17: 412.44 | H17: =ROUND(G17*1.1,2) | I17: =$B$6 | J17: =ROUND((H17*IF(FALSE,$B$4,$B$3)-F17-$B$5-$B$6)*$B$2,2) | K17: Repriced by pharmacist
A18: Yes | B18: Meloxicam | C18: Mobic | D18: 7.5mg | E18: 60 | F18: 1.99 | G18: 190.2 | H18: =ROUND(G18*1.1,2) | I18: =$B$6 | J18: =ROUND((H18*IF(FALSE,$B$4,$B$3)-F18-$B$5-$B$6)*$B$2,2) | K18: Priced
A19: Yes | B19: Meloxicam | C19: Mobic | D19: 15mg | E19: 30 | F19: 1.49 | G19: 145.35 | H19: =ROUND(G19*1.1,2) | I19: =$B$6 | J19: =ROUND((H19*IF(FALSE,$B$4,$B$3)-F19-$B$5-$B$6)*$B$2,2) | K19: Priced
A20: Yes | B20: Naproxen | D20: 550mg | E20: 60 | F20: 26.76 | G20: 352.67 | H20: =ROUND(G20*1.1,2) | I20: =$B$6 | J20: =ROUND((H20*IF(FALSE,$B$4,$B$3)-F20-$B$5-$B$6)*$B$2,2) | K20: Priced
A21: PAIN
A22: Yes | B22: Tramadol | C22: Ultram | D22: 50mg | E22: 60 | F22: 2.49 | G22: 50.4 | H22: =ROUND(G22*1.1,2) | I22: =$B$6 | J22: =ROUND((H22*IF(FALSE,$B$4,$B$3)-F22-$B$5-$B$6)*$B$2,2) | K22: Priced
A23: Yes | B23: Tramadol | C23: Ultram | D23: 50mg | E23: 90 | F23: 13.5 | G23: 82.08 | H23: =ROUND(G23*1.1,2) | I23: =$B$6 | J23: =ROUND((H23*IF(FALSE,$B$4,$B$3)-F23-$B$5-$B$6)*$B$2,2) | K23: Repriced by pharmacist
A24: Yes | B24: Tramadol ER | C24: Ultram ER | D24: 100mg | E24: 30 | F24: 34.95 | G24: 109.2 | H24: =ROUND(G24*1.1,2) | I24: =$B$6 | J24: =ROUND((H24*IF(FALSE,$B$4,$B$3)-F24-$B$5-$B$6)*$B$2,2) | K24: Priced
A25: Yes | B25: Tramadol ER | C25: Ultram ER | D25: 200mg | E25: 30 | F25: 56.99 | G25: 180.69 | H25: =ROUND(G25*1.1,2) | I25: =$B$6 | J25: =ROUND((H25*IF(FALSE,$B$4,$B$3)-F25-$B$5-$B$6)*$B$2,2) | K25: Priced
A26: Yes | B26: Tramadol ER | D26: 300mg | E26: 30 | F26: 105.99 | G26: 334.65 | H26: =ROUND(G26*1.1,2) | I26: =$B$6 | J26: =ROUND((H26*IF(FALSE,$B$4,$B$3)-F26-$B$5-$B$6)*$B$2,2) | K26: Priced
A27: STOOL SOFTENERS
A28: Yes | B28: Docusate | D28: 100mg | E28: 60 | F28: 0.81 | G28: 2.48 | H28: =ROUND(G28*1.1,2) | I28: =$B$6 | J28: =ROUND((H28*IF(FALSE,$B$4,$B$3)-F28-$B$5-$B$6)*$B$2,2) | K28: Priced
A29: Yes | B29: Laxacin (docusate/senna) | C29: Laxacin | D29: 50mg/8.6mg | E29: 60 | F29: 30 | G29: 130.02 | H29: =ROUND(G29*1.1,2) | I29: =$B$6 | J29: =ROUND((H29*IF(FALSE,$B$4,$B$3)-F29-$B$5-$B$6)*$B$2,2) | K29: Repriced by pharmacist
A30: No | B30: Narcosoft | C30: Narcosoft | D30: 60 | K30: Not available | L30: Pharmacist | M30: Enovachem product. We are currently unable to stock it. See the alternative below.
A31: Yes | B31: Lubiprostone (Amitiza) | C31: Amitiza | D31: 24mcg | E31: 60 | F31: 47.8 | G31: 440.84 | H31: =ROUND(G31*1.1,2) | I31: =$B$6 | J31: =ROUND((H31*IF(FALSE,$B$4,$B$3)-F31-$B$5-$B$6)*$B$2,2) | K31: Added by pharmacist | L31: Pharmacist | M31: Used in the treatment of opioid induced constipation.
A32: MUSCLE RELAXANTS
A33: Yes | B33: Baclofen | D33: 10mg | E33: 60 | F33: 59.4 | G33: 428.16 | H33: =ROUND(G33*1.1,2) | I33: =$B$6 | J33: =ROUND((H33*IF(FALSE,$B$4,$B$3)-F33-$B$5-$B$6)*$B$2,2) | K33: Priced
A34: Yes | B34: Baclofen | D34: 10mg | E34: 90 | F34: 89.1 | G34: 642.23 | H34: =ROUND(G34*1.1,2) | I34: =$B$6 | J34: =ROUND((H34*IF(FALSE,$B$4,$B$3)-F34-$B$5-$B$6)*$B$2,2) | K34: Priced
A35: Yes | B35: Baclofen | C35: Baclofen | D35: 20mg | E35: 60 | F35: 13.19 | G35: 307.8 | H35: =ROUND(G35*1.1,2) | I35: =$B$6 | J35: =ROUND((H35*IF(FALSE,$B$4,$B$3)-F35-$B$5-$B$6)*$B$2,2) | K35: Priced
A36: Yes | B36: Baclofen | C36: Baclofen | D36: 20mg | E36: 90 | F36: 31.5 | G36: 465.01 | H36: =ROUND(G36*1.1,2) | I36: =$B$6 | J36: =ROUND((H36*IF(FALSE,$B$4,$B$3)-F36-$B$5-$B$6)*$B$2,2) | K36: Repriced by pharmacist
A37: Yes | B37: Cyclobenzaprine | C37: Flexeril | D37: 10mg | E37: 60 | F37: 3.99 | G37: 98.4 | H37: =ROUND(G37*1.1,2) | I37: =$B$6 | J37: =ROUND((H37*IF(FALSE,$B$4,$B$3)-F37-$B$5-$B$6)*$B$2,2) | K37: Priced
A38: Yes | B38: Cyclobenzaprine | C38: Flexeril | D38: 10mg | E38: 90 | F38: 89.1 | G38: 542.08 | H38: =ROUND(G38*1.1,2) | I38: =$B$6 | J38: =ROUND((H38*IF(FALSE,$B$4,$B$3)-F38-$B$5-$B$6)*$B$2,2) | K38: Repriced by pharmacist
A39: Yes | B39: Cyclobenzaprine | C39: Fexmid | D39: 7.5mg | E39: 30 | F39: 24.99 | G39: 188.4 | H39: =ROUND(G39*1.1,2) | I39: =$B$6 | J39: =ROUND((H39*IF(FALSE,$B$4,$B$3)-F39-$B$5-$B$6)*$B$2,2) | K39: Priced
A40: Yes | B40: Cyclobenzaprine | C40: Fexmid | D40: 7.5mg | E40: 60 | F40: 49.99 | G40: 376.8 | H40: =ROUND(G40*1.1,2) | I40: =$B$6 | J40: =ROUND((H40*IF(FALSE,$B$4,$B$3)-F40-$B$5-$B$6)*$B$2,2) | K40: Priced
A41: Yes | B41: Cyclobenzaprine | C41: Fexmid | D41: 7.5mg | E41: 90 | F41: 74.95 | G41: 565.2 | H41: =ROUND(G41*1.1,2) | I41: =$B$6 | J41: =ROUND((H41*IF(FALSE,$B$4,$B$3)-F41-$B$5-$B$6)*$B$2,2) | K41: Priced
...

Sheet Full formulary
A1: THE FULL CATALOGUE. Copy any row and paste it into Your formulary.
A2: These lines read the assumptions on the first sheet, so they price the same way.
A4: Practice share | B4: ='Your formulary'!B2
A5: Oral collections | B5: ='Your formulary'!B3
A6: Topical collections | B6: ='Your formulary'!B4
A7: Dispensing fee / Rx | B7: ='Your formulary'!B5
A8: Shipping / order | B8: ='Your formulary'!B6
A10: Keep | B10: Medication | C10: Brand | D10: Strength | E10: Size | F10: Cost | G10: AWP | H10: PA fee | I10: Ship | J10: Per fill | K10: Category
A11: AED
B12: Pregabalin | C12: Lyrica | D12: 100mg | E12: 30 | F12: 45 | G12: 252.82 | H12: =ROUND(G12*1.1,2) | I12: ='Your formulary'!$B$6 | J12: =ROUND((H12*IF(FALSE,'Your formulary'!$B$4,'Your formulary'!$B$3)-F12-'Your formulary'!$B$5-'Your formulary'!$B$6)*'Your formulary'!$B$2,2) | K12: AED
A13: on list | B13: Pregabalin | C13: Lyrica | D13: 75mg | E13: 30 | F13: 45 | G13: 252.82 | H13: =ROUND(G13*1.1,2) | I13: ='Your formulary'!$B$6 | J13: =ROUND((H13*IF(FALSE,'Your formulary'!$B$4,'Your formulary'!$B$3)-F13-'Your formulary'!$B$5-'Your formulary'!$B$6)*'Your formulary'!$B$2,2) | K13: AED
B14: Pregabalin | C14: Lyrica | D14: 100mg | E14: 60 | F14: 90 | G14: 505.64 | H14: =ROUND(G14*1.1,2) | I14: ='Your formulary'!$B$6 | J14: =ROUND((H14*IF(FALSE,'Your formulary'!$B$4,'Your formulary'!$B$3)-F14-'Your formulary'!$B$5-'Your formulary'!$B$6)*'Your formulary'!$B$2,2) | K14: AED
A15: on list | B15: Pregabalin | C15: Lyrica | D15: 75mg | E15: 60 | F15: 90 | G15: 505.64 | H15: =ROUND(G15*1.1,2) | I15: ='Your formulary'!$B$6 | J15: =ROUND((H15*IF(FALSE,'Your formulary'!$B$4,'Your formulary'!$B$3)-F15-'Your formulary'!$B$5-'Your formulary'!$B$6)*'Your formulary'!$B$2,2) | K15: AED
A16: on list | B16: Pregabalin | C16: Pregabalin | D16: 75mg | E16: 90 | F16: 31.5 | G16: 787.93 | H16: =ROUND(G16*1.1,2) | I16: ='Your formulary'!$B$6 | J16: =ROUND((H16*IF(FALSE,'Your formulary'!$B$4,'Your formulary'!$B$3)-F16-'Your formulary'!$B$5-'Your formulary'!$B$6)*'Your formulary'!$B$2,2) | K16: AED
A17: ANALGESICS
A18: on list | B18: Duloxetine | C18: Cymbalta | D18: 60mg | E18: 30 | F18: 5.49 | G18: 235.5501 | H18: =ROUND(G18*1.1,2) | I18: ='Your formulary'!$B$6 | J18: =ROUND((H18*IF(FALSE,'Your formulary'!$B$4,'Your formulary'!$B$3)-F18-'Your formulary'!$B$5-'Your formulary'!$B$6)*'Your formulary'!$B$2,2) | K18: ANALGESICS
A19: on list | B19: Duloxetine | C19: Cymbalta | D19: 30mg | E19: 60 | F19: 10.99 | G19: 471.1 | H19: =ROUND(G19*1.1,2) | I19: ='Your formulary'!$B$6 | J19: =ROUND((H19*IF(FALSE,'Your formulary'!$B$4,'Your formulary'!$B$3)-F19-'Your formulary'!$B$5-'Your formulary'!$B$6)*'Your formulary'!$B$2,2) | K19: ANALGESICS
A20: on list | B20: Tramadol | C20: Tramadol | D20: 50mg | E20: 90 | F20: 13.5 | G20: 82.08 | H20: =ROUND(G20*1.1,2) | I20: ='Your formulary'!$B$6 | J20: =ROUND((H20*IF(FALSE,'Your formulary'!$B$4,'Your formulary'!$B$3)-F20-'Your formulary'!$B$5-'Your formulary'!$B$6)*'Your formulary'!$B$2,2) | K20: ANALGESICS
A21: on list | B21: Tramadol ER | C21: Tramadol | D21: 300mg | E21: 30 | F21: 105.99 | G21: 334.65 | H21: =ROUND(G21*1.1,2) | I21: ='Your formulary'!$B$6 | J21: =ROUND((H21*IF(FALSE,'Your formulary'!$B$4,'Your formulary'!$B$3)-F21-'Your formulary'!$B$5-'Your formulary'!$B$6)*'Your formulary'!$B$2,2) | K21: ANALGESICS
B22: Tramadol HCI | C22: Ultram | D22: 50mg | E22: 120 | F22: 6.69 | G22: 100.8 | H22: =ROUND(G22*1.1,2) | I22: ='Your formulary'!$B$6 | J22: =ROUND((H22*IF(FALSE,'Your formulary'!$B$4,'Your formulary'!$B$3)-F22-'Your formulary'!$B$5-'Your formulary'!$B$6)*'Your formulary'!$B$2,2) | K22: ANALGESICS
B23: Tramadol HCI | C23: Ultram | D23: 50mg | E23: 60 | F23: 2.49 | G23: 50.4 | H23: =ROUND(G23*1.1,2) | I23: ='Your formulary'!$B$6 | J23: =ROUND((H23*IF(FALSE,'Your formulary'!$B$4,'Your formulary'!$B$3)-F23-'Your formulary'!$B$5-'Your formulary'!$B$6)*'Your formulary'!$B$2,2) | K23: ANALGESICS
B24: Tramadol HCI ER | C24: Ultram ER | D24: 200mg | E24: 30 | F24: 56.99 | G24: 180.69 | H24: =ROUND(G24*1.1,2) | I24: ='Your formulary'!$B$6 | J24: =ROUND((H24*IF(FALSE,'Your formulary'!$B$4,'Your formulary'!$B$3)-F24-'Your formulary'!$B$5-'Your formulary'!$B$6)*'Your formulary'!$B$2,2) | K24: ANALGESICS
B25: Tramadol HCI ER | C25: Ultram ER | D25: 150mg | E25: 30 | F25: 0 | G25: 278.1 | H25: =ROUND(G25*1.1,2) | I25: ='Your formulary'!$B$6 | J25: =ROUND((H25*IF(FALSE,'Your formulary'!$B$4,'Your formulary'!$B$3)-F25-'Your formulary'!$B$5-'Your formulary'!$B$6)*'Your formulary'!$B$2,2) | K25: ANALGESICS
B26: Tramadol HCI ER | C26: Ultram ER | D26: 100mg | E26: 30 | F26: 34.95 | G26: 109.2 | H26: =ROUND(G26*1.1,2) | I26: ='Your formulary'!$B$6 | J26: =ROUND((H26*IF(FALSE,'Your formulary'!$B$4,'Your formulary'!$B$3)-F26-'Your formulary'!$B$5-'Your formulary'!$B$6)*'Your formulary'!$B$2,2) | K26: ANALGESICS
B27: Tramadol HCI ER | C27: Ultram ER | D27: 150mg | E27: 60 | F27: 0 | G27: 556.2 | H27: =ROUND(G27*1.1,2) | I27: ='Your formulary'!$B$6 | J27: =ROUND((H27*IF(FALSE,'Your formulary'!$B$4,'Your formulary'!$B$3)-F27-'Your formulary'!$B$5-'Your formulary'!$B$6)*'Your formulary'!$B$2,2) | K27: ANALGESICS
A28: ANTI CONVULSANTS
B29: Gabapentin | C29: Neurontin | D29: 300mg | E29: 30 | F29: 4.49 | G29: 39.92 | H29: =ROUND(G29*1.1,2) | I29: ='Your formulary'!$B$6 | J29: =ROUND((H29*IF(FALSE,'Your formulary'!$B$4,'Your formulary'!$B$3)-F29-'Your formulary'!$B$5-'Your formulary'!$B$6)*'Your formulary'!$B$2,2) | K29: ANTI CONVULSANTS
B30: Gabapentin | C30: Neurontin | D30: 600mg | E30: 30 | F30: 4.39 | G30: 75.9 | H30: =ROUND(G30*1.1,2) | I30: ='Your formulary'!$B$6 | J30: =ROUND((H30*IF(FALSE,'Your formulary'!$B$4,'Your formulary'!$B$3)-F30-'Your formulary'!$B$5-'Your formulary'!$B$6)*'Your formulary'!$B$2,2) | K30: ANTI CONVULSANTS
B31: Gabapentin | C31: Neurontin | D31: 100mg | E31: 30 | F31: 1.99 | G31: 15.9 | H31: =ROUND(G31*1.1,2) | I31: ='Your formulary'!$B$6 | J31: =ROUND((H31*IF(FALSE,'Your formulary'!$B$4,'Your formulary'!$B$3)-F31-'Your formulary'!$B$5-'Your formulary'!$B$6)*'Your formulary'!$B$2,2) | K31: ANTI CONVULSANTS
A32: on list | B32: Gabapentin | C32: Gabapentin | D32: 300mg | E32: 60 | F32: 10.8 | G32: 87.85 | H32: =ROUND(G32*1.1,2) | I32: ='Your formulary'!$B$6 | J32: =ROUND((H32*IF(FALSE,'Your formulary'!$B$4,'Your formulary'!$B$3)-F32-'Your formulary'!$B$5-'Your formulary'!$B$6)*'Your formulary'!$B$2,2) | K32: ANTI CONVULSANTS
B33: Gabapentin | C33: Neurontin | D33: 600mg | E33: 60 | F33: 8.99 | G33: 151.8 | H33: =ROUND(G33*1.1,2) | I33: ='Your formulary'!$B$6 | J33: =ROUND((H33*IF(FALSE,'Your formulary'!$B$4,'Your formulary'!$B$3)-F33-'Your formulary'!$B$5-'Your formulary'!$B$6)*'Your formulary'!$B$2,2) | K33: ANTI CONVULSANTS
A34: on list | B34: Gabapentin | C34: Gabapentin | D34: 400mg | E34: 90 | F34: 19.44 | G34: 159.04 | H34: =ROUND(G34*1.1,2) | I34: ='Your formulary'!$B$6 | J34: =ROUND((H34*IF(FALSE,'Your formulary'!$B$4,'Your formulary'!$B$3)-F34-'Your formulary'!$B$5-'Your formulary'!$B$6)*'Your formulary'!$B$2,2) | K34: ANTI CONVULSANTS
A35: on list | B35: Gabapentin | C35: Neurontin | D35: 600mg | E35: 90 | F35: 12.99 | G35: 227.7 | H35: =ROUND(G35*1.1,2) | I35: ='Your formulary'!$B$6 | J35: =ROUND((H35*IF(FALSE,'Your formulary'!$B$4,'Your formulary'!$B$3)-F35-'Your formulary'!$B$5-'Your formulary'!$B$6)*'Your formulary'!$B$2,2) | K35: ANTI CONVULSANTS
B36: Gabapentin | C36: Neurontin | D36: 300mg | E36: 90 | F36: 13.79 | G36: 119.76 | H36: =ROUND(G36*1.1,2) | I36: ='Your formulary'!$B$6 | J36: =ROUND((H36*IF(FALSE,'Your formulary'!$B$4,'Your formulary'!$B$3)-F36-'Your formulary'!$B$5-'Your formulary'!$B$6)*'Your formulary'!$B$2,2) | K36: ANTI CONVULSANTS
A37: on list | B37: Gabapentin | C37: Neurontin | D37: 100mg | E37: 90 | F37: 5.39 | G37: 47.7 | H37: =ROUND(G37*1.1,2) | I37: ='Your formulary'!$B$6 | J37: =ROUND((H37*IF(FALSE,'Your formulary'!$B$4,'Your formulary'!$B$3)-F37-'Your formulary'!$B$5-'Your formulary'!$B$6)*'Your formulary'!$B$2,2) | K37: ANTI CONVULSANTS
B38: Topiramate | C38: Topamax | D38: 50mg | E38: 30 | F38: 2.49 | G38: 141 | H38: =ROUND(G38*1.1,2) | I38: ='Your formulary'!$B$6 | J38: =ROUND((H38*IF(FALSE,'Your formulary'!$B$4,'Your formulary'!$B$3)-F38-'Your formulary'!$B$5-'Your formulary'!$B$6)*'Your formulary'!$B$2,2) | K38: ANTI CONVULSANTS
B39: Topiramate | C39: Topamax | D39: 100mg | E39: 60 | F39: 4.59 | G39: 372 | H39: =ROUND(G39*1.1,2) | I39: ='Your formulary'!$B$6 | J39: =ROUND((H39*IF(FALSE,'Your formulary'!$B$4,'Your formulary'!$B$3)-F39-'Your formulary'!$B$5-'Your formulary'!$B$6)*'Your formulary'!$B$2,2) | K39: ANTI CONVULSANTS
B40: Topiramate | C40: Topamax | D40: 50mg | E40: 60 | F40: 4.59 | G40: 282 | H40: =ROUND(G40*1.1,2) | I40: ='Your formulary'!$B$6 | J40: =ROUND((H40*IF(FALSE,'Your formulary'!$B$4,'Your formulary'!$B$3)-F40-'Your formulary'!$B$5-'Your formulary'!$B$6)*'Your formulary'!$B$2,2) | K40: ANTI CONVULSANTS
A41: ANTI NAUSEANT
A42: on list | B42: Ondansetron | C42: Zofran | D42: 4mg | E42: 30 | F42: 4.99 | G42: 743.4 | H42: =ROUND(G42*1.1,2) | I42: ='Your formulary'!$B$6 | J42: =ROUND((H42*IF(FALSE,'Your formulary'!$B$4,'Your formulary'!$B$3)-F42-'Your formulary'!$B$5-'Your formulary'!$B$6)*'Your formulary'!$B$2,2) | K42: ANTI NAUSEANT
...
